Workbook

Sheet README
A1: Make My Coffee — Cost, Profit & Voucher Playground
A2: Guardrails so voucher and shipping spend cannot out-run the profit they are meant to grow.
A4: HOW TO USE
A5: Yellow cells are inputs. | B5: Everything else is a formula and recalculates. Nothing is hard-coded.
A6: Start on Inputs. | B6: Costs, prices, volume, the free-shipping caps and the promo guardrails all live there.
A7: Plan promos on Vouchers. | B7: One row per campaign. The Verdict column says whether it is safe to run.
A8: Check Marketing Budget. | B8: It computes the single binding cap on promo spend, and the net profit after it.
A9: Stress-test on Scenarios. | B9: Blanket 5–30% discounts, and free shipping for everyone with and without the cap.
A11: FREE-SHIPPING RULES | B11: Lalamove quotes the real charge; these caps limit what we absorb.
A12: Voucher free shipping → ₱150 cap | B12: We absorb at most ₱150 on any order carrying a free-shipping voucher. If Lalamove quotes ₱200, we pay ₱150 and the customer pays ₱50. Inside Metro Manila a typical ₱150 quote is fully covered, so it reads as free; outside Metro Manila the cap bites. Editable per campaign in admin — but the default must stay ₱150 so a forgotten setting cannot be abused.
A13: Default free shipping → ₱1,200 minimum, ₱220 cap | B13: No voucher needed at or above a ₱1,200 order. We absorb at most ₱220 of the quote; the customer pays any excess. This replaces the old $30 (₱1,710) USD-denominated threshold.
A14: The two rules do not stack | B14: At or above ₱1,200 the order already ships free under the default rule, so a free-shipping voucher adds nothing. The planner values such a voucher at ₱0 and flags the campaign REDUNDANT.
A15: Zones are blended, not averaged | B15: The cap is applied per zone and then blended, because MIN(blended quote, cap) is not the same number as the blend of the capped amounts. Metro Manila share and both quote assumptions are inputs.
A16: The uncapped figure is carried too | B16: Every free-shipping campaign shows what it would cost with no cap enforced, and the roll-up shows the difference. That is what the ₱150 default is worth in pesos each month.
A18: THE FOUR PROMO GUARDRAILS | B18: All set on Inputs, all enforced by formula.
... A22: 4. Net profit floor | B22: A hard peso floor for monthly net profit. Promo spend is capped at whatever is left above it. Default ₱40,000.
B23: Marketing Budget takes the MINIMUM of caps 2, 3 and 4. The tightest binds — that is the real budget.
A25: WHAT THE MODEL CATCHES
A26: Discounts that break the margin floor | B26: At today's costs the max safe discount is roughly 39% on Starter and Classic, 38% on Reserve. Past that a sale still books revenue, but the margin is below the floor.
A27: Vouchers with no real minimum spend | B27: If min spend is at or below the average order value, the voucher mostly discounts orders you would have received anyway: margin given away with no basket lift. Flagged CHECK.
A28: Free-shipping vouchers that are redundant | B28: Min spend at or above ₱1,200 means the default rule already covers it. Flagged REDUNDANT.
A29: Promos that need impossible volume | B29: Break-even extra orders / month is what a campaign must generate ON TOP of baseline just to pay for itself. If that is a large fraction of current orders, the campaign is a bet, not a plan.
A30: Uplift assumed at zero | B30: Inputs has an incremental-uplift setting, left at 0%. Promo benefit is only counted once measured, which keeps every verdict conservative.
A32: WHAT CHANGED IN THIS FILE
A33: Brought up to date | B33: This copy was still the Aug-22 build: shipping fee $4.99, courier ₱100, 4 bottles/order, one flat ₱15 deco line. Now matches the current model — 2 bottles/order, separate ₱15.89 / ₱22.89 deco lines, paper bags and printouts, and 300 / 0 / 0 monthly volume.
A34: Shipping is no longer a profit centre | B34: The old model charged a flat ₱171 against a ₱150 courier cost — a quiet +₱21 per order, ₱3,150 a month, that only existed because the fee was a guess. With Lalamove quoting the real charge, shipping is pass-through: it earns the markup on Inputs (₱0 today) and costs whatever the free-shipping rules give away. Set a markup above zero if shipping should contribute again. This is why baseline net profit is lower than the previous ₱59,920.71.
A35: One bug fixed | B35: The free-shipping test on Analysis read cell C26, which was empty, so it always answered "NO — customer charged" by accident rather than by calculation.
A36: Inputs consolidated | B36: Sell prices, shots per bottle and monthly volume were typed into Analysis before; they are inputs, so they now live on Inputs and Analysis references them.
A37: Unchanged | B37: Cost per shot (₱18.47) and product economics (₱299 / ₱449 / ₱599 at 63.1–63.4% margin).
A39: NOT DONE HERE
A40: The app does not enforce these caps yet | B40: This sheet models the rules; nothing in the codebase implements them. The ₱150 voucher cap, the ₱1,200 / ₱220 default rule, and the admin field to edit the cap all still need building on the checkout and admin side, with ₱150 as the server-side default when the field is unset.

Sheet Inputs
A1: Make My Coffee — Cost & Profit Playground
A2: Edit the highlighted (yellow) cells. Everything else recalculates automatically.
A4: Ingredients & Utilities
A5: Coffee beans price | B5: 900 | C5: PHP per kg
A6: Ground coffee per shot | B6: 18 | C6: grams
A7: Shot volume | B7: 36 | C7: ml (reference only)
A8: Electricity rate | B8: 16 | C8: PHP per kWh
A9: Espresso machine power | B9: 3000 | C9: watts
A10: Grinder power | B10: 600 | C10: watts
A11: Machine run-time per shot | B11: 60 | C11: seconds (assumption)
A12: Grinder run-time per shot | B12: 15 | C12: seconds (assumption)
A14: Labor
A15: Labor cost per day | B15: 300 | C15: PHP per day
A16: Shots produced per day | B16: 210 | C16: throughput (assumption)
A18: Packaging (per bottle, by size)
A19: Bottle 120 mL | B19: 20 | C19: PHP — Starter
A20: Bottle 250 mL | B20: 12 | C20: PHP — Classic
A21: Bottle 300 mL | B21: 13.5 | C21: PHP — Reserve
A22: Small paper bag packaging | B22: 7.8 | C22: PHP per bag
A23: Large paper bag | B23: 14.8 | C23: PHP per bag
A24: Printouts | B24: 8.09 | C24: PHP — 3 stickers
A25: (120ml) Plastics, deco & printouts | B25: 15.89 | C25: PHP per unit
A26: (250,300ml) Plastics, deco & printouts | B26: 22.89 | C26: PHP per unit
A28: Delivery & Shipping
A29: USD -> PHP exchange rate | B29: 57 | C29: reference only — shipping is quoted in PHP by Lalamove
A30: Avg Lalamove quote — Metro Manila | B30: 150 | C30: PHP — assumption; the real charge comes from the API
A31: Avg Lalamove quote — outside Metro Manila | B31: 250 | C31: PHP — assumption; replace with real quotes
A32: % of orders inside Metro Manila | B32: 0.7 | C32: assumption
A33: Blended avg shipping quote | B33: =B32*B30+(1-B32)*B31
A34: Shipping markup charged on top of the quote | B34: 0 | C34: PHP — 0 means shipping is pure pass-through and earns nothing
A35: Avg bottles per order | B35: 2 | C35: assumption
A37: Free-shipping rules ★ NEW
A38: Default free shipping — minimum order | B38: 1200 | C38: PHP — no voucher needed at or above this
A39: Default free shipping — max we absorb | B39: 220 | C39: PHP — customer pays any quote above this
A40: Voucher free shipping — max we absorb | B40: 150 | C40: PHP — admin-editable; leave at 150 so a forgotten setting cannot be abused
A41: % of orders that reach the minimum order | B41: 0.05 | C41: assumption — AOV is well below the minimum today
A43: We absorb per free-shipped order (computed)
A44: Default rule — Metro Manila | B44: =MIN(B30,B39)
A45: Default rule — outside Metro Manila | B45: =MIN(B31,B39) | C45: cap bites: customer pays the excess
A46: Default rule — blended | B46: =B32*B44+(1-B32)*B45
...

Sheet Analysis
A1: Cost per Shot
A3: Beans per shot | B3: =Inputs!B5/1000*Inputs!B6
A4: Electricity per shot | B4: =(Inputs!B9*Inputs!B11+Inputs!B10*Inputs!B12)/1000/3600*Inputs!B8
A5: Labor per shot | B5: =Inputs!B15/Inputs!B16
A6: TOTAL cost per shot | B6: =SUM(B3:B5)
A9: Product Profitability — before any discount
A11: Product | B11: Shots | C11: Bottle | D11: Deco | E11: Beans | F11: Electricity | G11: Labor | H11: Total Cost | I11: Sell Price | J11: Profit | K11: Margin % | L11: Markup % | M11: Max safe discount % | N11: Price at that discount | O11: Break-even unit uplift
A12: Aconchego Starter | B12: =Inputs!$B$68 | C12: =Inputs!$B$19 | D12: =Inputs!$B$25 | E12: =B12*$B$3 | F12: =B12*$B$4 | G12: =B12*$B$5 | H12: =C12+D12+E12+F12+G12 | I12: =Inputs!$B$65 | J12: =I12-H12 | K12: =IF(I12=0,0,J12/I12) | L12: =IF(H12=0,0,J12/H12) | M12: =1-H12/(I12*(1-Inputs!$B$53)) | N12: =I12*(1-M12) | O12: =IF((N12-H12)<=0,"n/a",J12/(N12-H12)-1)
A13: Aconchego Classic | B13: =Inputs!$B$69 | C13: =Inputs!$B$20 | D13: =Inputs!$B$26 | E13: =B13*$B$3 | F13: =B13*$B$4 | G13: =B13*$B$5 | H13: =C13+D13+E13+F13+G13 | I13: =Inputs!$B$66 | J13: =I13-H13 | K13: =IF(I13=0,0,J13/I13) | L13: =IF(H13=0,0,J13/H13) | M13: =1-H13/(I13*(1-Inputs!$B$53)) | N13: =I13*(1-M13) | O13: =IF((N13-H13)<=0,"n/a",J13/(N13-H13)-1)
A14: Aconchego Reserve | B14: =Inputs!$B$70 | C14: =Inputs!$B$21 | D14: =Inputs!$B$26 | E14: =B14*$B$3 | F14: =B14*$B$4 | G14: =B14*$B$5 | H14: =C14+D14+E14+F14+G14 | I14: =Inputs!$B$67 | J14: =I14-H14 | K14: =IF(I14=0,0,J14/I14) | L14: =IF(H14=0,0,J14/H14) | M14: =1-H14/(I14*(1-Inputs!$B$53)) | N14: =I14*(1-M14) | O14: =IF((N14-H14)<=0,"n/a",J14/(N14-H14)-1)
A15: Profit above is per-bottle unit economics; shipping is per-order (see below). The three highlighted columns are the guardrail: at the margin floor set on Inputs, that is the deepest discount each product can carry, and the extra volume it must produce just to stand still.
A18: Monthly Projection — BEFORE vouchers
A19: Product | B19: Units / month | C19: Revenue | D19: COGS | E19: Gross Profit
A20: =A12 | B20: =Inputs!$B$60 | C20: =B20*I12 | D20: =B20*H12 | E20: =C20-D20
A21: =A13 | B21: =Inputs!$B$61 | C21: =B21*I13 | D21: =B21*H13 | E21: =C21-D21
A22: =A14 | B22: =Inputs!$B$62 | C22: =B22*I14 | D22: =B22*H14 | E22: =C22-D22
A23: Subtotal | B23: =SUM(B20:B22) | C23: =SUM(C20:C22) | D23: =SUM(D20:D22) | E23: =SUM(E20:E22)
A25: Shipping — Lalamove pass-through, subsidies capped
A26: Total units / month | B26: =B23
A27: Orders / month | B27: =B26/Inputs!$B$35
A28: Avg order value | B28: =IF(B27=0,0,C23/B27)
A29: Orders reaching the free-ship minimum | B29: =B27*Inputs!$B$41 | C29: these ship free by default — no voucher involved
A30: Shipping markup collected | B30: =(B27-B29)*Inputs!$B$34 | C30: zero while the markup on Inputs is zero
A31: Default free-shipping subsidy (capped) | B31: =B29*Inputs!$B$46
A32: Net shipping result | B32: =B30-B31 | C32: negative = shipping is a cost centre
A33: Other monthly expenses | B33: ='Other Expenses'!D16 | C33: from the Other Expenses tracker — 0 until quantities are filled in
A34: NET PROFIT / month (before vouchers) | B34: =E23+B32-B33 | C34: the baseline every promo is measured against
A35: Gross margin % | B35: =IF(C23=0,0,E23/C23)
A36: COGS as % of revenue | B36: =IF(C23=0,0,D23/C23) | C36: used by the voucher planner
A38: Shipping used to be modelled as a flat ₱171 charge against a ₱150 courier cost — a quiet +₱21 per order, ₱3,150 a month of "profit" that only existed because the fee was a guess. With Lalamove quoting the real charge, shipping is pass-through: it earns the markup on Inputs (₱0 today) and costs whatever subsidy the free-shipping rules hand out. Set a markup above zero if you intend shipping to contribute again.

Sheet Vouchers
A1: Voucher & Promo Planner
A2: One row per campaign. Yellow cells are yours; Verdict applies the guardrails from Inputs. Nothing here changes a price — it says which promos survive a peso-for-peso profit test.
A4: Baseline per-order economics (from Analysis)
A5: Avg order value (AOV) | B5: =Analysis!B28
A6: COGS as % of revenue | B6: =Analysis!B36
A7: COGS per order | B7: =B5*B6
A8: Shipping result per non-free order | B8: =Inputs!$B$34 | C8: the markup — shipping is otherwise pass-through
A9: Contribution per order (before promo) | B9: =B5-B7+B8 | C9: every peso of promo comes straight out of this
A10: Orders / month | B10: =Analysis!B27
A11: Free-shipping subsidy per redemption (capped) | B11: =Inputs!$B$49 | C11: blended Metro Manila / outside; the cap is on Inputs
A13: Max safe discount by product — at the margin floor on Inputs
A14: Product | B14: Sell price | C14: Unit cost | D14: Margin now | E14: Max safe discount % | F14: Price at that discount | G14: Break-even unit uplift
A15: =Analysis!A12 | B15: =Analysis!I12 | C15: =Analysis!H12 | D15: =Analysis!K12 | E15: =Analysis!M12 | F15: =Analysis!N12 | G15: =Analysis!O12
A16: =Analysis!A13 | B16: =Analysis!I13 | C16: =Analysis!H13 | D16: =Analysis!K13 | E16: =Analysis!M13 | F16: =Analysis!N13 | G16: =Analysis!O13
A17: =Analysis!A14 | B17: =Analysis!I14 | C17: =Analysis!H14 | D17: =Analysis!K14 | E17: =Analysis!M14 | F17: =Analysis!N14 | G17: =Analysis!O14
A19: Campaign planner
A20: Edit columns A–G (yellow). H onward is computed.
A21: Campaign | B21: Status | C21: Type | D21: Value | E21: Min spend (₱) | F21: Redemptions / month | G21: Campaign AOV (₱) | H21: Discount ₱ / redemption | I21: Shipping subsidy — capped | J21: Subsidy if cap NOT enforced | K21: Saved by the cap | L21: Promo cost / redemption | M21: Effective discount % | N21: Promo cost as % of order profit | O21: Total promo cost / month | P21: Gross revenue from these orders | Q21: Order contribution after promo | R21: Product margin after promo | S21: Break-even extra orders / month | T21: Verdict
A22: Launch10 — 10% off, no minimum | B22: Active | C22: % off | D22: 0.1 | E22: 0 | F22: 60 | G22: 598 | H22: =IF($B22="Off",0,IF($C22="% off",$D22*$G22,IF($C22="₱ off",MIN($D22,$G22),0))) | I22: =IF($B22="Off",0,IF($C22="Free shipping",IF($G22>=Inputs!$B$38,0,Inputs!$B$49),0)) | J22: =IF($B22="Off",0,IF($C22="Free shipping",IF($G22>=Inputs!$B$38,0,Inputs!$B$50),0)) | K22: =J22-I22 | L22: =H22+I22 | M22: =IF($G22=0,0,L22/$G22) | N22: =IF($B$9=0,0,L22/$B$9) | O22: =IF($B22="Active",$F22*L22,0) | P22: =IF($B22="Active",$F22*$G22,0) | Q22: =$G22*(1-$B$6)-H22-I22+IF(I22>0,0,Inputs!$B$34) | R22: =IF(($G22-H22)=0,0,($G22*(1-$B$6)-H22)/($G22-H22)) | S22: =IF(Q22<=0,"n/a",O22/Q22) | T22: =IF($B22="Off","—",IF(Q22<0,"STOP — loses money on every order",IF(R22<Inputs!$B$53,"STOP — margin below the floor",IF(AND($C22="Free shipping",$E22>=Inputs!$B$38),"REDUNDANT — these orders already ship free by default",IF(N22>0.5,"CHECK — promo eats >50% of the order's profit",IF($E22<$B$5,"CHECK — min spend <= AOV, subsidises orders you'd get anyway","OK"))))))
A23: Free shipping weekend | B23: Active | C23: Free shipping | D23: 0 | E23: 0 | F23: 40 | G23: 598 | H23: =IF($B23="Off",0,IF($C23="% off",$D23*$G23,IF($C23="₱ off",MIN($D23,$G23),0))) | I23: =IF($B23="Off",0,IF($C23="Free shipping",IF($G23>=Inputs!$B$38,0,Inputs!$B$49),0)) | J23: =IF($B23="Off",0,IF($C23="Free shipping",IF($G23>=Inputs!$B$38,0,Inputs!$B$50),0)) | K23: =J23-I23 | L23: =H23+I23 | M23: =IF($G23=0,0,L23/$G23) | N23: =IF($B$9=0,0,L23/$B$9) | O23: =IF($B23="Active",$F23*L23,0) | P23: =IF($B23="Active",$F23*$G23,0) | Q23: =$G23*(1-$B$6)-H23-I23+IF(I23>0,0,Inputs!$B$34) | R23: =IF(($G23-H23)=0,0,($G23*(1-$B$6)-H23)/($G23-H23)) | S23: =IF(Q23<=0,"n/a",O23/Q23) | T23: =IF($B23="Off","—",IF(Q23<0,"STOP — loses money on every order",IF(R23<Inputs!$B$53,"STOP — margin below the floor",IF(AND($C23="Free shipping",$E23>=Inputs!$B$38),"REDUNDANT — these orders already ship free by default",IF(N23>0.5,"CHECK — promo eats >50% of the order's profit",IF($E23<$B$5,"CHECK — min spend <= AOV, subsidises orders you'd get anyway","OK"))))))
A24: ₱100 off ₱1,200+ (basket builder) | B24: Draft | C24: ₱ off | D24: 100 | E24: 1200 | F24: 25 | G24: 1300 | H24: =IF($B24="Off",0,IF($C24="% off",$D24*$G24,IF($C24="₱ off",MIN($D24,$G24),0))) | I24: =IF($B24="Off",0,IF($C24="Free shipping",IF($G24>=Inputs!$B$38,0,Inputs!$B$49),0)) | J24: =IF($B24="Off",0,IF($C24="Free shipping",IF($G24>=Inputs!$B$38,0,Inputs!$B$50),0)) | K24: =J24-I24 | L24: =H24+I24 | M24: =IF($G24=0,0,L24/$G24) | N24: =IF($B$9=0,0,L24/$B$9) | O24: =IF($B24="Active",$F24*L24,0) | P24: =IF($B24="Active",$F24*$G24,0) | Q24: =$G24*(1-$B$6)-H24-I24+IF(I24>0,0,Inputs!$B$34) | R24: =IF(($G24-H24)=0,0,($G24*(1-$B$6)-H24)/($G24-H24)) | S24: =IF(Q24<=0,"n/a",O24/Q24) | T24: =IF($B24="Off","—",IF(Q24<0,"STOP — loses money on every order",IF(R24<Inputs!$B$53,"STOP — margin below the floor",IF(AND($C24="Free shipping",$E24>=Inputs!$B$38),"REDUNDANT — these orders already ship free by default",IF(N24>0.5,"CHECK — promo eats >50% of the order's profit",IF($E24<$B$5,"CHECK — min spend <= AOV, subsidises orders you'd get anyway","OK"))))))
A25: Bundle40 — 40% off clearance | B25: Draft | C25: % off | D25: 0.4 | E25: 0 | F25: 30 | G25: 598 | H25: =IF($B25="Off",0,IF($C25="% off",$D25*$G25,IF($C25="₱ off",MIN($D25,$G25),0))) | I25: =IF($B25="Off",0,IF($C25="Free shipping",IF($G25>=Inputs!$B$38,0,Inputs!$B$49),0)) | J25: =IF($B25="Off",0,IF($C25="Free shipping",IF($G25>=Inputs!$B$38,0,Inputs!$B$50),0)) | K25: =J25-I25 | L25: =H25+I25 | M25: =IF($G25=0,0,L25/$G25) | N25: =IF($B$9=0,0,L25/$B$9) | O25: =IF($B25="Active",$F25*L25,0) | P25: =IF($B25="Active",$F25*$G25,0) | Q25: =$G25*(1-$B$6)-H25-I25+IF(I25>0,0,Inputs!$B$34) | R25: =IF(($G25-H25)=0,0,($G25*(1-$B$6)-H25)/($G25-H25)) | S25: =IF(Q25<=0,"n/a",O25/Q25) | T25: =IF($B25="Off","—",IF(Q25<0,"STOP — loses money on every order",IF(R25<Inputs!$B$53,"STOP — margin below the floor",IF(AND($C25="Free shipping",$E25>=Inputs!$B$38),"REDUNDANT — these orders already ship free by default",IF(N25>0.5,"CHECK — promo eats >50% of the order's profit",IF($E25<$B$5,"CHECK — min spend <= AOV, subsidises orders you'd get anyway","OK"))))))
B26: Off | C26: % off | D26: 0 | E26: 0 | F26: 0 | G26: 598 | H26: =IF($B26="Off",0,IF($C26="% off",$D26*$G26,IF($C26="₱ off",MIN($D26,$G26),0))) | I26: =IF($B26="Off",0,IF($C26="Free shipping",IF($G26>=Inputs!$B$38,0,Inputs!$B$49),0)) | J26: =IF($B26="Off",0,IF($C26="Free shipping",IF($G26>=Inputs!$B$38,0,Inputs!$B$50),0)) | K26: =J26-I26 | L26: =H26+I26 | M26: =IF($G26=0,0,L26/$G26) | N26: =IF($B$9=0,0,L26/$B$9) | O26: =IF($B26="Active",$F26*L26,0) | P26: =IF($B26="Active",$F26*$G26,0) | Q26: =$G26*(1-$B$6)-H26-I26+IF(I26>0,0,Inputs!$B$34) | R26: =IF(($G26-H26)=0,0,($G26*(1-$B$6)-H26)/($G26-H26)) | S26: =IF(Q26<=0,"n/a",O26/Q26) | T26: =IF($B26="Off","—",IF(Q26<0,"STOP — loses money on every order",IF(R26<Inputs!$B$53,"STOP — margin below the floor",IF(AND($C26="Free shipping",$E26>=Inputs!$B$38),"REDUNDANT — these orders already ship free by default",IF(N26>0.5,"CHECK — promo eats >50% of the order's profit",IF($E26<$B$5,"CHECK — min spend <= AOV, subsidises orders you'd get anyway","OK"))))))
B27: Off | C27: % off | D27: 0 | E27: 0 | F27: 0 | G27: 598 | H27: =IF($B27="Off",0,IF($C27="% off",$D27*$G27,IF($C27="₱ off",MIN($D27,$G27),0))) | I27: =IF($B27="Off",0,IF($C27="Free shipping",IF($G27>=Inputs!$B$38,0,Inputs!$B$49),0)) | J27: =IF($B27="Off",0,IF($C27="Free shipping",IF($G27>=Inputs!$B$38,0,Inputs!$B$50),0)) | K27: =J27-I27 | L27: =H27+I27 | M27: =IF($G27=0,0,L27/$G27) | N27: =IF($B$9=0,0,L27/$B$9) | O27: =IF($B27="Active",$F27*L27,0) | P27: =IF($B27="Active",$F27*$G27,0) | Q27: =$G27*(1-$B$6)-H27-I27+IF(I27>0,0,Inputs!$B$34) | R27: =IF(($G27-H27)=0,0,($G27*(1-$B$6)-H27)/($G27-H27)) | S27: =IF(Q27<=0,"n/a",O27/Q27) | T27: =IF($B27="Off","—",IF(Q27<0,"STOP — loses money on every order",IF(R27<Inputs!$B$53,"STOP — margin below the floor",IF(AND($C27="Free shipping",$E27>=Inputs!$B$38),"REDUNDANT — these orders already ship free by default",IF(N27>0.5,"CHECK — promo eats >50% of the order's profit",IF($E27<$B$5,"CHECK — min spend <= AOV, subsidises orders you'd get anyway","OK"))))))
B28: Off | C28: % off | D28: 0 | E28: 0 | F28: 0 | G28: 598 | H28: =IF($B28="Off",0,IF($C28="% off",$D28*$G28,IF($C28="₱ off",MIN($D28,$G28),0))) | I28: =IF($B28="Off",0,IF($C28="Free shipping",IF($G28>=Inputs!$B$38,0,Inputs!$B$49),0)) | J28: =IF($B28="Off",0,IF($C28="Free shipping",IF($G28>=Inputs!$B$38,0,Inputs!$B$50),0)) | K28: =J28-I28 | L28: =H28+I28 | M28: =IF($G28=0,0,L28/$G28) | N28: =IF($B$9=0,0,L28/$B$9) | O28: =IF($B28="Active",$F28*L28,0) | P28: =IF($B28="Active",$F28*$G28,0) | Q28: =$G28*(1-$B$6)-H28-I28+IF(I28>0,0,Inputs!$B$34) | R28: =IF(($G28-H28)=0,0,($G28*(1-$B$6)-H28)/($G28-H28)) | S28: =IF(Q28<=0,"n/a",O28/Q28) | T28: =IF($B28="Off","—",IF(Q28<0,"STOP — loses money on every order",IF(R28<Inputs!$B$53,"STOP — margin below the floor",IF(AND($C28="Free shipping",$E28>=Inputs!$B$38),"REDUNDANT — these orders already ship free by default",IF(N28>0.5,"CHECK — promo eats >50% of the order's profit",IF($E28<$B$5,"CHECK — min spend <= AOV, subsidises orders you'd get anyway","OK"))))))
B29: Off | C29: % off | D29: 0 | E29: 0 | F29: 0 | G29: 598 | H29: =IF($B29="Off",0,IF($C29="% off",$D29*$G29,IF($C29="₱ off",MIN($D29,$G29),0))) | I29: =IF($B29="Off",0,IF($C29="Free shipping",IF($G29>=Inputs!$B$38,0,Inputs!$B$49),0)) | J29: =IF($B29="Off",0,IF($C29="Free shipping",IF($G29>=Inputs!$B$38,0,Inputs!$B$50),0)) | K29: =J29-I29 | L29: =H29+I29 | M29: =IF($G29=0,0,L29/$G29) | N29: =IF($B$9=0,0,L29/$B$9) | O29: =IF($B29="Active",$F29*L29,0) | P29: =IF($B29="Active",$F29*$G29,0) | Q29: =$G29*(1-$B$6)-H29-I29+IF(I29>0,0,Inputs!$B$34) | R29: =IF(($G29-H29)=0,0,($G29*(1-$B$6)-H29)/($G29-H29)) | S29: =IF(Q29<=0,"n/a",O29/Q29) | T29: =IF($B29="Off","—",IF(Q29<0,"STOP — loses money on every order",IF(R29<Inputs!$B$53,"STOP — margin below the floor",IF(AND($C29="Free shipping",$E29>=Inputs!$B$38),"REDUNDANT — these orders already ship free by default",IF(N29>0.5,"CHECK — promo eats >50% of the order's profit",IF($E29<$B$5,"CHECK — min spend <= AOV, subsidises orders you'd get anyway","OK"))))))
A30: TOTAL (active campaigns) | F30: =SUMIF($B$22:$B$29,"Active",F22:F29) | O30: =SUM(O22:O29) | P30: =SUM(P22:P29)
A32: Roll-up
A33: Total promo cost / month | B33: =O30 | C33: active campaigns only
A34: Free-shipping subsidy — with the cap | B34: =SUMPRODUCT(($B$22:$B$29="Active")*$F$22:$F$29*$I$22:$I$29)
A35: Free-shipping subsidy — if the cap is NOT enforced | B35: =SUMPRODUCT(($B$22:$B$29="Active")*$F$22:$F$29*$J$22:$J$29) | C35: what a forgotten cap would cost
A36: Protected by the cap | B36: =B35-B34 | C36: the whole point of the ₱150 default
A37: Contribution from assumed uplift | B37: =Inputs!$B$57*B10*B9 | C37: zero until uplift is measured — deliberately conservative
A38: Net profit BEFORE vouchers | B38: =Analysis!B34
A39: Net profit AFTER vouchers | B39: =B38-B33+B37
A40: Change vs before | B40: =B39-B38
A41: Promo spend as % of gross profit | B41: =IF(Analysis!E23=0,0,B33/Analysis!E23)
A42: Verdict | B42: =IF(B39<Inputs!$B$56,"BREACH — net profit below the floor on Inputs",IF(B33>'Marketing Budget'!$B$13,"OVER BUDGET — see Marketing Budget","OK — within every cap"))

Sheet Marketing Budget
A1: Marketing Budget — the ceiling promo spend may not cross
A2: Three independent caps. The tightest one binds. Spend against that number, not against a wish.
A4: Where the money is now
A5: Gross revenue / month | B5: =Analysis!C23
A6: Gross profit / month | B6: =Analysis!E23
A7: Net profit / month (before any promo) | B7: =Analysis!B34
A9: Three caps — the binding one wins
A10: Cap A — % of gross revenue | B10: =Inputs!$B$54*B5 | C10: share of revenue allowed
A11: Cap B — % of gross profit | B11: =Inputs!$B$55*B6 | C11: share of gross profit allowed
A12: Cap C — keep net profit above the floor | B12: =MAX(0,B7-Inputs!$B$56) | C12: whatever sits above the net profit floor
A13: BINDING CAP — max marketing spend / month | B13: =MIN(B10:B12) | C13: the real budget
A14: Which cap binds | B14: =IF(B13=B10,"A — % of revenue",IF(B13=B11,"B — % of gross profit","C — net profit floor"))
A16: Planned spend
A17: Voucher / discount cost (from Vouchers) | B17: =Vouchers!B33
A18: Other marketing spend (ads, samples, collabs) | B18: 0 | C18: PHP / month — editable
A19: TOTAL marketing spend | B19: =B17+B18
A20: Headroom vs binding cap | B20: =B13-B19 | C20: negative means you are over
A21: Spend as % of gross revenue | B21: =IF(B5=0,0,B19/B5)
A22: Spend as % of gross profit | B22: =IF(B6=0,0,B19/B6)
A23: Extra exposure if shipping caps are not enforced | B23: =Vouchers!B36 | C23: add this to the spend above if an admin clears a cap
A25: Result
A26: Net profit AFTER marketing | B26: =B7-B19+Vouchers!B37
A27: Net margin after marketing | B27: =IF(B5=0,0,B26/B5)
A28: Net profit floor (from Inputs) | B28: =Inputs!$B$56
A29: VERDICT | B29: =IF(B19>B13,"OVER BUDGET — cut "&TEXT(B19-B13,"₱#,##0")&" of promo spend",IF(B26<Inputs!$B$56,"BREACH — net profit below the floor","OK — within every cap, "&TEXT(B20,"₱#,##0")&" of headroom left"))
A31: Cap C is the one that actually protects the business: it is the only cap expressed in profit rather than as a share of a number that promos themselves inflate. Discounting lifts revenue while shrinking profit, so a revenue-share cap alone loosens exactly when it should tighten.

Sheet Scenarios
A1: Scenarios — what a blanket discount does to the month
A2: Applied to every order, at today's volume, with zero assumed uplift. Read the last three columns together.
A4: Scenario | B4: Promo cost / month | C4: Net profit / month | D4: Net margin | E4: vs profit floor | F4: Contribution per order after | G4: Break-even extra orders / month | H4: Break-even uplift needed | I4: Verdict
A5: 0% off every order | B5: =0.0*Analysis!$C$23 | C5: =Analysis!$B$34-B5 | D5: =IF(Analysis!$C$23=0,0,C5/Analysis!$C$23) | E5: =C5-Inputs!$B$56 | F5: =Vouchers!$B$9-0.0*Vouchers!$B$5 | G5: =IF(F5<=0,"n/a",B5/F5) | H5: =IF(F5<=0,"n/a",B5/F5/Analysis!$B$27) | I5: =IF(F5<=0,"STOP — the order itself loses money",IF(C5<Inputs!$B$56,"BREACH — below the profit floor",IF(B5>'Marketing Budget'!$B$13,"OVER CAP — exceeds the binding cap","OK")))
A6: 5% off every order | B6: =0.05*Analysis!$C$23 | C6: =Analysis!$B$34-B6 | D6: =IF(Analysis!$C$23=0,0,C6/Analysis!$C$23) | E6: =C6-Inputs!$B$56 | F6: =Vouchers!$B$9-0.05*Vouchers!$B$5 | G6: =IF(F6<=0,"n/a",B6/F6) | H6: =IF(F6<=0,"n/a",B6/F6/Analysis!$B$27) | I6: =IF(F6<=0,"STOP — the order itself loses money",IF(C6<Inputs!$B$56,"BREACH — below the profit floor",IF(B6>'Marketing Budget'!$B$13,"OVER CAP — exceeds the binding cap","OK")))
A7: 10% off every order | B7: =0.1*Analysis!$C$23 | C7: =Analysis!$B$34-B7 | D7: =IF(Analysis!$C$23=0,0,C7/Analysis!$C$23) | E7: =C7-Inputs!$B$56 | F7: =Vouchers!$B$9-0.1*Vouchers!$B$5 | G7: =IF(F7<=0,"n/a",B7/F7) | H7: =IF(F7<=0,"n/a",B7/F7/Analysis!$B$27) | I7: =IF(F7<=0,"STOP — the order itself loses money",IF(C7<Inputs!$B$56,"BREACH — below the profit floor",IF(B7>'Marketing Budget'!$B$13,"OVER CAP — exceeds the binding cap","OK")))
A8: 15% off every order | B8: =0.15*Analysis!$C$23 | C8: =Analysis!$B$34-B8 | D8: =IF(Analysis!$C$23=0,0,C8/Analysis!$C$23) | E8: =C8-Inputs!$B$56 | F8: =Vouchers!$B$9-0.15*Vouchers!$B$5 | G8: =IF(F8<=0,"n/a",B8/F8) | H8: =IF(F8<=0,"n/a",B8/F8/Analysis!$B$27) | I8: =IF(F8<=0,"STOP — the order itself loses money",IF(C8<Inputs!$B$56,"BREACH — below the profit floor",IF(B8>'Marketing Budget'!$B$13,"OVER CAP — exceeds the binding cap","OK")))
A9: 20% off every order | B9: =0.2*Analysis!$C$23 | C9: =Analysis!$B$34-B9 | D9: =IF(Analysis!$C$23=0,0,C9/Analysis!$C$23) | E9: =C9-Inputs!$B$56 | F9: =Vouchers!$B$9-0.2*Vouchers!$B$5 | G9: =IF(F9<=0,"n/a",B9/F9) | H9: =IF(F9<=0,"n/a",B9/F9/Analysis!$B$27) | I9: =IF(F9<=0,"STOP — the order itself loses money",IF(C9<Inputs!$B$56,"BREACH — below the profit floor",IF(B9>'Marketing Budget'!$B$13,"OVER CAP — exceeds the binding cap","OK")))
A10: 25% off every order | B10: =0.25*Analysis!$C$23 | C10: =Analysis!$B$34-B10 | D10: =IF(Analysis!$C$23=0,0,C10/Analysis!$C$23) | E10: =C10-Inputs!$B$56 | F10: =Vouchers!$B$9-0.25*Vouchers!$B$5 | G10: =IF(F10<=0,"n/a",B10/F10) | H10: =IF(F10<=0,"n/a",B10/F10/Analysis!$B$27) | I10: =IF(F10<=0,"STOP — the order itself loses money",IF(C10<Inputs!$B$56,"BREACH — below the profit floor",IF(B10>'Marketing Budget'!$B$13,"OVER CAP — exceeds the binding cap","OK")))
A11: 30% off every order | B11: =0.3*Analysis!$C$23 | C11: =Analysis!$B$34-B11 | D11: =IF(Analysis!$C$23=0,0,C11/Analysis!$C$23) | E11: =C11-Inputs!$B$56 | F11: =Vouchers!$B$9-0.3*Vouchers!$B$5 | G11: =IF(F11<=0,"n/a",B11/F11) | H11: =IF(F11<=0,"n/a",B11/F11/Analysis!$B$27) | I11: =IF(F11<=0,"STOP — the order itself loses money",IF(C11<Inputs!$B$56,"BREACH — below the profit floor",IF(B11>'Marketing Budget'!$B$13,"OVER CAP — exceeds the binding cap","OK")))
A12: Free shipping on every order — cap enforced | B12: =Analysis!$B$27*(1-Inputs!$B$41)*Inputs!$B$49 | C12: =Analysis!$B$34-B12 | D12: =IF(Analysis!$C$23=0,0,C12/Analysis!$C$23) | E12: =C12-Inputs!$B$56 | F12: =Vouchers!$B$9-Inputs!$B$49 | G12: =IF(F12<=0,"n/a",B12/F12) | H12: =IF(F12<=0,"n/a",B12/F12/Analysis!$B$27) | I12: =IF(F12<=0,"STOP — the order itself loses money",IF(C12<Inputs!$B$56,"BREACH — below the profit floor",IF(B12>'Marketing Budget'!$B$13,"OVER CAP — exceeds the binding cap","OK")))
A13: Free shipping on every order — cap NOT enforced | B13: =Analysis!$B$27*(1-Inputs!$B$41)*Inputs!$B$50 | C13: =Analysis!$B$34-B13 | D13: =IF(Analysis!$C$23=0,0,C13/Analysis!$C$23) | E13: =C13-Inputs!$B$56 | F13: =Vouchers!$B$9-Inputs!$B$50 | G13: =IF(F13<=0,"n/a",B13/F13) | H13: =IF(F13<=0,"n/a",B13/F13/Analysis!$B$27) | I13: =IF(F13<=0,"STOP — the order itself loses money",IF(C13<Inputs!$B$56,"BREACH — below the profit floor",IF(B13>'Marketing Budget'!$B$13,"OVER CAP — exceeds the binding cap","OK")))
A15: Break-even uplift needed is the honest test: the extra order volume, as a % of today's orders, that the discount must create before it has paid for itself. The last two rows are the same promo with and without the shipping cap enforced — the gap between them is what the ₱150 default is worth every month.

Sheet Other Expenses
A1: Make My Coffee — Expenses Tracker
A2: Edit the highlighted (yellow) cells. The monthly total feeds the projection on Analysis.
A4: Packaging Print | B4: Price | C4: Qty / month | D4: Monthly cost
A5: Printed bottle label sticker | C5: 0 | D5: =IF(B5="",0,B5*C5) | E5: per page
A6: Printed packaging thank you sticker | C6: 0 | D6: =IF(B6="",0,B6*C6) | E6: per page
A7: Printed coffee recipe / guide card | C7: 0 | D7: =IF(B7="",0,B7*C7) | E7: per page
A8: Total Printing Expenses | D8: =SUM(D5:D7)
A10: Cleaning Materials | B10: Price | C10: Qty / month | D10: Monthly cost
A11: Tissue/Paper Towels | B11: 33 | C11: 0 | D11: =B11*C11 | E11: per pack
A12: Towel | B12: 60 | C12: 0 | D12: =B12*C12 | E12: per pack
A13: Trash bag | B13: 30 | C13: 0 | D13: =B13*C13 | E13: per roll
A14: Total Cleaning Expenses | D14: =SUM(D11:D13)
A16: TOTAL OTHER EXPENSES / month | D16: =D8+D14
A18: Quantities default to 0, so nothing is charged until you fill in Qty / month. The projection on Analysis picks the total up automatically.
